Workbook

Sheet LEIA-ME
A1: Observatório SJC – PIB dos Municípios (IBGE)
A2: São José dos Campos (código IBGE 3549904). Dados tratados no Colab e conferidos nesta planilha.
A4: Números principais
A5: Último ano com PIB | B5: =MAX(fato_PIB!$A$2:$A$23) -> 2023
A6: PIB a preços correntes (R$ bilhões) | B6: =INDEX(fato_PIB!$B$2:$B$23,MATCH(B5,fato_PIB!$A$2:$A$23,0))/1000000000 -> 61.394524
A7: PIB per capita (R$) | B7: =INDEX(fato_PIB!$X$2:$X$23,MATCH(B5,fato_PIB!$A$2:$A$23,0)) -> 86361.081
A8: Crescimento deflacionado no último ano | B8: =INDEX(fato_PIB!$V$2:$V$23,MATCH(B5,fato_PIB!$A$2:$A$23,0))/100 -> 0.035832
A9: Crescimento médio anual 2002–último ano (deflacionado) | B9: =(INDEX(fato_PIB!$N$2:$N$23,MATCH(B5,fato_PIB!$A$2:$A$23,0))/INDEX(fato_PIB!$N$2:$N$23,MATCH(2002,fato_PIB!$A$2:$A$23,0)))^(1/(B5-2002))-1 -> 0.015673347
A10: Participação no PIB do estado de SP | B10: =INDEX(fato_PIB!$AI$2:$AI$23,MATCH(B5,fato_PIB!$A$2:$A$23,0))/100 -> 0.0178
A11: Último ano com detalhamento por setor | B11: =SUMPRODUCT(MAX((fato_PIB!$I$2:$I$23="Completo")*fato_PIB!$A$2:$A$23)) -> 2021
A12: Participação da indústria no VAB (último ano com setor) | B12: =INDEX(fato_PIB!$AA$2:$AA$23,MATCH(B11,fato_PIB!$A$2:$A$23,0))/100 -> 0.423905
A15: Como usar
A16: • Comece pela aba Perguntas: cada linha responde a uma pergunta do cliente com o número calculado e diz onde ver o detalhe.
A17: • As abas de análise (Serie_PIB, Estrutura_Setorial, Participacao_Regional, Cruzamento_RAIS) são fórmulas sobre as abas de dados.
A18: • As abas de dados (fato_PIB, fato_VAB_setorial, dIPCA, dPopulacao, fato_Participacoes) são os CSVs do Colab sem alteração.
A19: • Antes de citar um número, veja a aba Problemas_Dados: ela diz o que não é comparável entre anos.
A20: • Valores 'R$ 2023' = valores corrigidos pelo IPCA para preços de 2023, para comparar anos diferentes.
A22: Abas
A23: Aba | B23: O que contém
A24: Perguntas | B24: 15 perguntas que os dados respondem, com resposta calculada, cuidado e visual sugerido.
A25: Serie_PIB | B25: PIB, crescimento, índice 2010=100, população e PIB per capita de 2002 a 2023, com gráficos.
A26: Estrutura_Setorial | B26: Peso da agropecuária, indústria, serviços e adm. pública no valor adicionado (2002–2021).
A27: Participacao_Regional | B27: Peso de SJC no PIB da microrregião, mesorregião, estado, Sudeste e Brasil.
A28: Cruzamento_RAIS | B28: Emprego formal (RAIS 2024) x valor adicionado (PIB) por setor.
A29: Deflator_IPCA | B29: Como os valores foram corrigidos para R$ de 2023, recalculado e conferido.
A30: Conferencia | B30: Recalcula os indicadores do Colab e mostra a diferença (deve ser zero ou arredondamento).
A31: Problemas_Dados | B31: Limitações e quebras de série encontradas, com o tratamento sugerido.
A32: Dicionario | B32: Significado e unidade de cada coluna de cada CSV.
A33: Glossario | B33: PIB, VAB, deflacionar, per capita, CAGR e outros termos, em linguagem simples.
A34: Sugestoes | B34: Modelo para o Power BI, medidas, páginas e padrões de legenda.
... A36: fato_PIB … log_tratamento | B36: Os CSVs do Colab, como vieram.
A38: Fontes
A39: • IBGE – PIB dos Municípios, SIDRA tabela 5938 (PIB, VAB por setor, impostos e participações).
A40: • IBGE – IPCA, SIDRA tabela 1737 (variação acumulada em 12 meses, dezembro).
A41: • IBGE – Estimativas da População (tab. 6579), Contagem 2007 (tab. 793), Censos 2010 (tab. 1378) e 2022 (tab. 4709).
A42: • MTE – RAIS 2024, via CNAE_RAIS_SJC_2024.xlsx (só na aba Cruzamento_RAIS).

Sheet Perguntas
A1: Perguntas que os dados do IBGE respondem
A2: Resposta calculada por fórmula. 'Cuidado' diz o que dizer junto com o número.
A4: Nº | B4: Pergunta | C4: Resposta | D4: Unidade | E4: Complemento | F4: Valor do complemento | G4: Cuidado ao usar | H4: Onde ver | I4: Visual sugerido no Power BI
A5: 1 | B5: Quanto São José dos Campos produziu no último ano? | C5: ='LEIA-ME'!B6 -> 61.394524 | D5: R$ bilhões | E5: Ano | F5: ='LEIA-ME'!$B$5 -> 2023 | G5: Valor nominal (do próprio ano). | H5: Serie_PIB | I5: Cartão de KPI
A6: 2 | B6: Quanto isso dá por habitante? | C6: ='LEIA-ME'!B7 -> 86361.081 | D6: R$ por pessoa | E6: Ano | F6: ='LEIA-ME'!$B$5 -> 2023 | G6: A população de 2023 é interpolada. | H6: Serie_PIB | I6: Cartão de KPI
A7: 3 | B7: A economia cresceu de verdade nos últimos 20 anos? | C7: ='LEIA-ME'!B9 -> 0.015673347 | D7: % ao ano (2002 até o último ano) | E7: PIB em R$ 2023 no 1º ano (R$ bi) | F7: =INDEX(fato_PIB!$N$2:$N$23,MATCH(2002,fato_PIB!$A$2:$A$23,0))/1000000000 -> 44.288856 | G7: Descontada a inflação (IPCA). Não é o 'PIB real' oficial do IBGE. | H7: Serie_PIB | I7: Linha do PIB em R$ 2023
A8: 4 | B8: E na última década? | C8: =(INDEX(fato_PIB!$N$2:$N$23,MATCH('LEIA-ME'!$B$5,fato_PIB!$A$2:$A$23,0))/INDEX(fato_PIB!$N$2:$N$23,MATCH(2013,fato_PIB!$A$2:$A$23,0)))^(1/('LEIA-ME'!$B$5-2013))-1 -> 0.020272486 | D8: % ao ano (2013 até o último ano) | E8: Índice no último ano (2010=100) | F8: =INDEX(fato_PIB!$W$2:$W$23,MATCH('LEIA-ME'!$B$5,fato_PIB!$A$2:$A$23,0)) -> 112.0549 | G8: Média anual composta (CAGR). | H8: Serie_PIB | I8: Cartão de KPI
A9: 5 | B9: Qual foi o pior ano? | C9: =MIN(fato_PIB!$V$2:$V$23)/100 -> -0.135458 | D9: variação deflacionada | E9: Ano | F9: =INDEX(fato_PIB!$A$2:$A$23,MATCH(MIN(fato_PIB!$V$2:$V$23),fato_PIB!$V$2:$V$23,0)) -> 2020 | G9: Pandemia. | H9: Serie_PIB | I9: Colunas de crescimento por ano
A10: 6 | B10: Qual foi o melhor ano? | C10: =MAX(fato_PIB!$V$2:$V$23)/100 -> 0.184562 | D10: variação deflacionada | E10: Ano | F10: =INDEX(fato_PIB!$A$2:$A$23,MATCH(MAX(fato_PIB!$V$2:$V$23),fato_PIB!$V$2:$V$23,0)) -> 2022 | G10: 2022 pode ter efeito de mudança de metodologia do IBGE. Confirmar antes de destacar. | H10: Serie_PIB / Problemas_Dados | I10: Colunas de crescimento por ano
A11: 7 | B11: SJC ganhou ou perdeu peso no estado de SP? | C11: =Participacao_Regional!D27 -> -0.79 | D11: pontos percentuais desde 2002 | E11: Participação no último ano | F11: =Participacao_Regional!D26 -> 0.0178 | G11: Perder peso não é encolher: o estado cresceu mais rápido. | H11: Participacao_Regional | I11: Linha de participação
A12: 8 | B12: E no Brasil? | C12: =Participacao_Regional!F27 -> -0.34 | D12: pontos percentuais desde 2002 | E12: Participação no último ano | F12: =Participacao_Regional!F26 -> 0.0056 | G12: Idem. | H12: Participacao_Regional | I12: Linha de participação
A13: 9 | B13: Quanto SJC pesa na própria microrregião? | C13: =INDEX(fato_PIB!$AG$2:$AG$23,MATCH('LEIA-ME'!$B$5,fato_PIB!$A$2:$A$23,0))/100 -> 0.4885 | D13: do PIB da microrregião | E13: Na mesorregião | F13: =INDEX(fato_PIB!$AF$2:$AF$23,MATCH('LEIA-ME'!$B$5,fato_PIB!$A$2:$A$23,0))/100 -> 0.3172 | G13: SJC é o polo econômico da região. | H13: Participacao_Regional | I13: Cartão de KPI
A14: 10 | B14: SJC ainda é uma cidade industrial? | C14: ='LEIA-ME'!B12 -> 0.423905 | D14: do VAB é indústria | E14: Serviços (exceto adm. pública) | F14: =INDEX(fato_PIB!$AB$2:$AB$23,MATCH('LEIA-ME'!$B$11,fato_PIB!$A$2:$A$23,0))/100 -> 0.50114 | G14: Último dado por setor é de 2021. | H14: Estrutura_Setorial | I14: Linhas de participação por setor
A15: 11 | B15: Quando a indústria pesou mais? | C15: =Estrutura_Setorial!D26 -> 0.590208 | D15: maior peso no VAB | E15: Ano | F15: =Estrutura_Setorial!E26 -> 2004 | G15: Queda até 2013 e recuperação a partir de 2016. | H15: Estrutura_Setorial | I15: Linhas de participação por setor
A16: 12 | B16: E quando pesou menos? | C16: =Estrutura_Setorial!D27 -> 0.322561 | D16: menor peso no VAB | E16: Ano | F16: =Estrutura_Setorial!E27 -> 2013 | G16: Idem. | H16: Estrutura_Setorial | I16: Linhas de participação por setor
A17: 13 | B17: Quanto do PIB é imposto? | C17: =INDEX(fato_PIB!$AD$2:$AD$23,MATCH('LEIA-ME'!$B$11,fato_PIB!$A$2:$A$23,0))/100 -> 0.141152 | D17: do PIB | E17: Ano | F17: ='LEIA-ME'!$B$11 -> 2021 | G17: Impostos líquidos de subsídios sobre produtos. | H17: Estrutura_Setorial | I17: Cartão de KPI
A18: 14 | B18: Quantos empregos formais há por 1.000 habitantes? | C18: =Cruzamento_RAIS!B17 -> 285.22289 | D18: vínculos por 1.000 hab. | E18: PIB por vínculo (R$ mil) | F18: =Cruzamento_RAIS!B16 -> 296.99794 | G18: Não inclui informais nem servidores públicos (ausentes da base RAIS). | H18: Cruzamento_RAIS | I18: Cartão de KPI
A19: 15 | B19: A indústria emprega na mesma proporção em que produz? | C19: =Cruzamento_RAIS!C8 -> 0.24795735 | D19: dos vínculos são da indústria | E19: % do VAB que é indústria | F19: =Cruzamento_RAIS!D8 -> 0.423905 | G19: Anos diferentes (RAIS 2024 x VAB 2021). Use como ordem de grandeza. | H19: Cruzamento_RAIS | I19: Barras: % vínculos x % VAB

Sheet Serie_PIB
A1: PIB de São José dos Campos, 2002–2023
A2: Correntes = valor do ano. R$ 2023 = corrigido pelo IPCA. Crescimento deflacionado = variação do PIB em R$ 2023.
A4: Ano | B4: PIB corrente (R$ bi) | C4: PIB em R$ 2023 (R$ bi) | D4: Crescimento nominal | E4: Crescimento deflacionado | F4: Índice PIB (2010=100) | G4: População | H4: Fonte da população | I4: PIB per capita (R$) | J4: PIB per capita em R$ 2023 | K4: Detalhamento por setor
A5: =fato_PIB!A2 -> 2002 | B5: =fato_PIB!B2/1000000000 -> 13.335899 | C5: =fato_PIB!N2/1000000000 -> 44.288856 | D5: =IF(fato_PIB!U2="","",fato_PIB!U2/100) | E5: =IF(fato_PIB!V2="","",fato_PIB!V2/100) | F5: =fato_PIB!W2 -> 80.8343 | G5: =fato_PIB!J2 -> 559710 | H5: =fato_PIB!K2 -> Estimativas da População (tab. 6579) | I5: =fato_PIB!X2 -> 23826.444 | J5: =fato_PIB!Y2 -> 79128.22 | K5: =fato_PIB!I2 -> Completo
A6: =fato_PIB!A3 -> 2003 | B6: =fato_PIB!B3/1000000000 -> 15.87102 | C6: =fato_PIB!N3/1000000000 -> 48.223291 | D6: =IF(fato_PIB!U3="","",fato_PIB!U3/100) -> 0.190097 | E6: =IF(fato_PIB!V3="","",fato_PIB!V3/100) -> 0.088836 | F6: =fato_PIB!W3 -> 88.0152 | G6: =fato_PIB!J3 -> 569177 | H6: =fato_PIB!K3 -> Estimativas da População (tab. 6579) | I6: =fato_PIB!X3 -> 27884.156 | J6: =fato_PIB!Y3 -> 84724.595 | K6: =fato_PIB!I3 -> Completo
A7: =fato_PIB!A4 -> 2004 | B7: =fato_PIB!B4/1000000000 -> 18.673609 | C7: =fato_PIB!N4/1000000000 -> 52.731241 | D7: =IF(fato_PIB!U4="","",fato_PIB!U4/100) -> 0.176585 | E7: =IF(fato_PIB!V4="","",fato_PIB!V4/100) -> 0.093481 | F7: =fato_PIB!W4 -> 96.243 | G7: =fato_PIB!J4 -> 589050 | H7: =fato_PIB!K4 -> Estimativas da População (tab. 6579) | I7: =fato_PIB!X4 -> 31701.229 | J7: =fato_PIB!Y4 -> 89519.126 | K7: =fato_PIB!I4 -> Completo
A8: =fato_PIB!A5 -> 2005 | B8: =fato_PIB!B5/1000000000 -> 18.461686 | C8: =fato_PIB!N5/1000000000 -> 49.326147 | D8: =IF(fato_PIB!U5="","",fato_PIB!U5/100) -> -0.011349 | E8: =IF(fato_PIB!V5="","",fato_PIB!V5/100) -> -0.064575 | F8: =fato_PIB!W5 -> 90.0281 | G8: =fato_PIB!J5 -> 600049 | H8: =fato_PIB!K5 -> Estimativas da População (tab. 6579) | I8: =fato_PIB!X5 -> 30766.964 | J8: =fato_PIB!Y5 -> 82203.532 | K8: =fato_PIB!I5 -> Completo
A9: =fato_PIB!A6 -> 2006 | B9: =fato_PIB!B6/1000000000 -> 18.940246 | C9: =fato_PIB!N6/1000000000 -> 49.064155 | D9: =IF(fato_PIB!U6="","",fato_PIB!U6/100) -> 0.025922 | E9: =IF(fato_PIB!V6="","",fato_PIB!V6/100) -> -0.005311 | F9: =fato_PIB!W6 -> 89.55 | G9: =fato_PIB!J6 -> 610965 | H9: =fato_PIB!K6 -> Estimativas da População (tab. 6579) | I9: =fato_PIB!X6 -> 31000.542 | J9: =fato_PIB!Y6 -> 80305.999 | K9: =fato_PIB!I6 -> Completo
A10: =fato_PIB!A7 -> 2007 | B10: =fato_PIB!B7/1000000000 -> 21.861254 | C10: =fato_PIB!N7/1000000000 -> 54.213039 | D10: =IF(fato_PIB!U7="","",fato_PIB!U7/100) -> 0.154222 | E10: =IF(fato_PIB!V7="","",fato_PIB!V7/100) -> 0.104942 | F10: =fato_PIB!W7 -> 98.9475 | G10: =fato_PIB!J7 -> 594948 | H10: =fato_PIB!K7 -> Contagem da População 2007 (tab. 793) | I10: =fato_PIB!X7 -> 36744.815 | J10: =fato_PIB!Y7 -> 91122.315 | K10: =fato_PIB!I7 -> Completo
A11: =fato_PIB!A8 -> 2008 | B11: =fato_PIB!B8/1000000000 -> 24.884337 | C11: =fato_PIB!N8/1000000000 -> 58.271849 | D11: =IF(fato_PIB!U8="","",fato_PIB!U8/100) -> 0.138285 | E11: =IF(fato_PIB!V8="","",fato_PIB!V8/100) -> 0.074868 | F11: =fato_PIB!W8 -> 106.3555 | G11: =fato_PIB!J8 -> 609229 | H11: =fato_PIB!K8 -> Estimativas da População (tab. 6579) | I11: =fato_PIB!X8 -> 40845.621 | J11: =fato_PIB!Y8 -> 95648.515 | K11: =fato_PIB!I8 -> Completo
A12: =fato_PIB!A9 -> 2009 | B12: =fato_PIB!B9/1000000000 -> 24.566242 | C12: =fato_PIB!N9/1000000000 -> 55.149999 | D12: =IF(fato_PIB!U9="","",fato_PIB!U9/100) -> -0.012783 | E12: =IF(fato_PIB!V9="","",fato_PIB!V9/100) -> -0.053574 | F12: =fato_PIB!W9 -> 100.6576 | G12: =fato_PIB!J9 -> 615871 | H12: =fato_PIB!K9 -> Estimativas da População (tab. 6579) | I12: =fato_PIB!X9 -> 39888.616 | J12: =fato_PIB!Y9 -> 89547.971 | K12: =fato_PIB!I9 -> Completo
A13: =fato_PIB!A10 -> 2010 | B13: =fato_PIB!B10/1000000000 -> 25.84813 | C13: =fato_PIB!N10/1000000000 -> 54.789702 | D13: =IF(fato_PIB!U10="","",fato_PIB!U10/100) -> 0.052181 | E13: =IF(fato_PIB!V10="","",fato_PIB!V10/100) -> -0.006533 | F13: =fato_PIB!W10 -> 100 | G13: =fato_PIB!J10 -> 629921 | H13: =fato_PIB!K10 -> Censo 2010 (tab. 1378) | I13: =fato_PIB!X10 -> 41033.923 | J13: =fato_PIB!Y10 -> 86978.688 | K13: =fato_PIB!I10 -> Completo
A14: =fato_PIB!A11 -> 2011 | B14: =fato_PIB!B11/1000000000 -> 25.51874 | C14: =fato_PIB!N11/1000000000 -> 50.790142 | D14: =IF(fato_PIB!U11="","",fato_PIB!U11/100) -> -0.012743 | E14: =IF(fato_PIB!V11="","",fato_PIB!V11/100) -> -0.072998 | F14: =fato_PIB!W11 -> 92.7002 | G14: =fato_PIB!J11 -> 636876 | H14: =fato_PIB!K11 -> Estimativas da População (tab. 6579) | I14: =fato_PIB!X11 -> 40068.616 | J14: =fato_PIB!Y11 -> 79748.872 | K14: =fato_PIB!I11 -> Completo
A15: =fato_PIB!A12 -> 2012 | B15: =fato_PIB!B12/1000000000 -> 26.584749 | C15: =fato_PIB!N12/1000000000 -> 49.992279 | D15: =IF(fato_PIB!U12="","",fato_PIB!U12/100) -> 0.041774 | E15: =IF(fato_PIB!V12="","",fato_PIB!V12/100) -> -0.015709 | F15: =fato_PIB!W12 -> 91.2439 | G15: =fato_PIB!J12 -> 643603 | H15: =fato_PIB!K12 -> Estimativas da População (tab. 6579) | I15: =fato_PIB!X12 -> 41306.13 | J15: =fato_PIB!Y12 -> 77675.647 | K15: =fato_PIB!I12 -> Completo
A16: =fato_PIB!A13 -> 2013 | B16: =fato_PIB!B13/1000000000 -> 28.2901 | C16: =fato_PIB!N13/1000000000 -> 50.230545 | D16: =IF(fato_PIB!U13="","",fato_PIB!U13/100) -> 0.064148 | E16: =IF(fato_PIB!V13="","",fato_PIB!V13/100) -> 0.004766 | F16: =fato_PIB!W13 -> 91.6788 | G16: =fato_PIB!J13 -> 673255 | H16: =fato_PIB!K13 -> Estimativas da População (tab. 6579) | I16: =fato_PIB!X13 -> 42019.889 | J16: =fato_PIB!Y13 -> 74608.498 | K16: =fato_PIB!I13 -> Completo
... A26: =fato_PIB!A23 -> 2023 | B26: =fato_PIB!B23/1000000000 -> 61.394524 | C26: =fato_PIB!N23/1000000000 -> 61.394524 | D26: =IF(fato_PIB!U23="","",fato_PIB!U23/100) -> 0.083688 | E26: =IF(fato_PIB!V23="","",fato_PIB!V23/100) -> 0.035832 | F26: =fato_PIB!W23 -> 112.0549 | G26: =fato_PIB!J23 -> 710905 | H26: =fato_PIB!K23 -> Interpolação linear (tratamento do projeto) | I26: =fato_PIB!X23 -> 86361.081 | J26: =fato_PIB!Y23 -> 86361.081 | K26: =fato_PIB!I23 -> Somente PIB total
A28: Atenção: 2007, 2010 e 2022 usam contagem/censo; 2023 é interpolada. Saltos no per capita nesses anos vêm em parte da população, não só do PIB.
A29: O crescimento de 2022 pode misturar efeito de mudança de metodologia do IBGE (ver Problemas_Dados).

Sheet Estrutura_Setorial
A1: Estrutura da economia: peso de cada setor no valor adicionado (VAB)
A2: 2002–2021. O IBGE não publicou o detalhamento por setor de 2022 e 2023 (ver Problemas_Dados).
A4: Ano | B4: Agropecuária | C4: Indústria | D4: Serviços (exceto adm. pública) | E4: Adm. pública | F4: Total | G4: VAB indústria R$ 2023 (R$ bi) | H4: VAB serviços R$ 2023 (R$ bi) | I4: Impostos / PIB
A5: =fato_PIB!A2 -> 2002 | B5: =fato_PIB!Z2/100 -> 0.000659 | C5: =fato_PIB!AA2/100 -> 0.527449 | D5: =fato_PIB!AB2/100 -> 0.406157 | E5: =fato_PIB!AC2/100 -> 0.065736 | F5: =SUM(B5:E5) -> 1.000001 | G5: =fato_PIB!Q2/1000000000 -> 19.576752 | H5: =fato_PIB!R2/1000000000 -> 15.07488 | I5: =fato_PIB!AD2/100 -> 0.161958
A6: =fato_PIB!A3 -> 2003 | B6: =fato_PIB!Z3/100 -> 0.001165 | C6: =fato_PIB!AA3/100 -> 0.562629 | D6: =fato_PIB!AB3/100 -> 0.375012 | E6: =fato_PIB!AC3/100 -> 0.061194 | F6: =SUM(B6:E6) -> 1 | G6: =fato_PIB!Q3/1000000000 -> 23.355582 | H6: =fato_PIB!R3/1000000000 -> 15.567325 | I6: =fato_PIB!AD3/100 -> 0.139181
A7: =fato_PIB!A4 -> 2004 | B7: =fato_PIB!Z4/100 -> 0.001136 | C7: =fato_PIB!AA4/100 -> 0.590208 | D7: =fato_PIB!AB4/100 -> 0.352873 | E7: =fato_PIB!AC4/100 -> 0.055782 | F7: =SUM(B7:E7) -> 0.999999 | G7: =fato_PIB!Q4/1000000000 -> 26.196065 | H7: =fato_PIB!R4/1000000000 -> 15.6621 | I7: =fato_PIB!AD4/100 -> 0.158289
A8: =fato_PIB!A5 -> 2005 | B8: =fato_PIB!Z5/100 -> 0.000854 | C8: =fato_PIB!AA5/100 -> 0.552855 | D8: =fato_PIB!AB5/100 -> 0.382337 | E8: =fato_PIB!AC5/100 -> 0.063955 | F8: =SUM(B8:E8) -> 1.000001 | G8: =fato_PIB!Q5/1000000000 -> 23.314944 | H8: =fato_PIB!R5/1000000000 -> 16.12387 | I8: =fato_PIB!AD5/100 -> 0.145039
A9: =fato_PIB!A6 -> 2006 | B9: =fato_PIB!Z6/100 -> 0.000891 | C9: =fato_PIB!AA6/100 -> 0.522718 | D9: =fato_PIB!AB6/100 -> 0.406579 | E9: =fato_PIB!AC6/100 -> 0.069812 | F9: =SUM(B9:E9) -> 1 | G9: =fato_PIB!Q6/1000000000 -> 21.833584 | H9: =fato_PIB!R6/1000000000 -> 16.9825 | I9: =fato_PIB!AD6/100 -> 0.14868
A10: =fato_PIB!A7 -> 2007 | B10: =fato_PIB!Z7/100 -> 0.000899 | C10: =fato_PIB!AA7/100 -> 0.550185 | D10: =fato_PIB!AB7/100 -> 0.38529 | E10: =fato_PIB!AC7/100 -> 0.063626 | F10: =SUM(B10:E10) -> 1 | G10: =fato_PIB!Q7/1000000000 -> 25.756 | H10: =fato_PIB!R7/1000000000 -> 18.036705 | I10: =fato_PIB!AD7/100 -> 0.136494
A11: =fato_PIB!A8 -> 2008 | B11: =fato_PIB!Z8/100 -> 0.00068 | C11: =fato_PIB!AA8/100 -> 0.548066 | D11: =fato_PIB!AB8/100 -> 0.38897 | E11: =fato_PIB!AC8/100 -> 0.062283 | F11: =SUM(B11:E11) -> 0.999999 | G11: =fato_PIB!Q8/1000000000 -> 27.177436 | H11: =fato_PIB!R8/1000000000 -> 19.288208 | I11: =fato_PIB!AD8/100 -> 0.149026
A12: =fato_PIB!A9 -> 2009 | B12: =fato_PIB!Z9/100 -> 0.000852 | C12: =fato_PIB!AA9/100 -> 0.509746 | D12: =fato_PIB!AB9/100 -> 0.416517 | E12: =fato_PIB!AC9/100 -> 0.072885 | F12: =SUM(B12:E12) -> 1 | G12: =fato_PIB!Q9/1000000000 -> 24.390618 | H12: =fato_PIB!R9/1000000000 -> 19.929742 | I12: =fato_PIB!AD9/100 -> 0.132391
A13: =fato_PIB!A10 -> 2010 | B13: =fato_PIB!Z10/100 -> 0.000856 | C13: =fato_PIB!AA10/100 -> 0.485399 | D13: =fato_PIB!AB10/100 -> 0.439257 | E13: =fato_PIB!AC10/100 -> 0.074489 | F13: =SUM(B13:E13) -> 1.000001 | G13: =fato_PIB!Q10/1000000000 -> 22.51044 | H13: =fato_PIB!R10/1000000000 -> 20.37057 | I13: =fato_PIB!AD10/100 -> 0.15358
A14: =fato_PIB!A11 -> 2011 | B14: =fato_PIB!Z11/100 -> 0.000728 | C14: =fato_PIB!AA11/100 -> 0.405087 | D14: =fato_PIB!AB11/100 -> 0.514306 | E14: =fato_PIB!AC11/100 -> 0.079879 | F14: =SUM(B14:E14) -> 1 | G14: =fato_PIB!Q11/1000000000 -> 17.147577 | H14: =fato_PIB!R11/1000000000 -> 21.77091 | I14: =fato_PIB!AD11/100 -> 0.166558
A15: =fato_PIB!A12 -> 2012 | B15: =fato_PIB!Z12/100 -> 0.000735 | C15: =fato_PIB!AA12/100 -> 0.355178 | D15: =fato_PIB!AB12/100 -> 0.560459 | E15: =fato_PIB!AC12/100 -> 0.083628 | F15: =SUM(B15:E15) -> 1 | G15: =fato_PIB!Q12/1000000000 -> 14.64992 | H15: =fato_PIB!R12/1000000000 -> 23.117052 | I15: =fato_PIB!AD12/100 -> 0.174939
A16: =fato_PIB!A13 -> 2013 | B16: =fato_PIB!Z13/100 -> 0.000972 | C16: =fato_PIB!AA13/100 -> 0.322561 | D16: =fato_PIB!AB13/100 -> 0.583059 | E16: =fato_PIB!AC13/100 -> 0.093408 | F16: =SUM(B16:E16) -> 1 | G16: =fato_PIB!Q13/1000000000 -> 13.38354 | H16: =fato_PIB!R13/1000000000 -> 24.191987 | I16: =fato_PIB!AD13/100 -> 0.173978
... A24: =fato_PIB!A21 -> 2021 | B24: =fato_PIB!Z21/100 -> 0.000657 | C24: =fato_PIB!AA21/100 -> 0.423905 | D24: =fato_PIB!AB21/100 -> 0.50114 | E24: =fato_PIB!AC21/100 -> 0.074298 | F24: =SUM(B24:E24) -> 1 | G24: =fato_PIB!Q21/1000000000 -> 18.216599 | H24: =fato_PIB!R21/1000000000 -> 21.535623 | I24: =fato_PIB!AD21/100 -> 0.141152
A26: Maior peso da indústria na série: | D26: =MAX(C5:C24) -> 0.590208 | E26: =INDEX(A5:A24,MATCH(D26,C5:C24,0)) -> 2004
A27: Menor peso da indústria na série: | D27: =MIN(C5:C24) -> 0.322561 | E27: =INDEX(A5:A24,MATCH(D27,C5:C24,0)) -> 2013
A28: A agropecuária fica abaixo de 0,2% em todos os anos, por isso não aparece no gráfico.

Sheet Participacao_Regional
A1: Peso de SJC no PIB da região, do estado e do país
A2: Participação do PIB de SJC no PIB de cada recorte, 2002–2023 (IBGE, tab. 5938).
A4: Ano | B4: Microrregião | C4: Mesorregião | D4: Estado de SP | E4: Região Sudeste | F4: Brasil
A5: =fato_PIB!A2 -> 2002 | B5: =fato_PIB!AG2/100 -> 0.5595 | C5: =fato_PIB!AF2/100 -> 0.4521 | D5: =fato_PIB!AI2/100 -> 0.0257 | E5: =fato_PIB!AE2/100 -> 0.0156 | F5: =fato_PIB!AH2/100 -> 0.009
A6: =fato_PIB!A3 -> 2003 | B6: =fato_PIB!AG3/100 -> 0.5605 | C6: =fato_PIB!AF3/100 -> 0.4568 | D6: =fato_PIB!AI3/100 -> 0.0268 | E6: =fato_PIB!AE3/100 -> 0.0164 | F6: =fato_PIB!AH3/100 -> 0.0092
A7: =fato_PIB!A4 -> 2004 | B7: =fato_PIB!AG4/100 -> 0.5753 | C7: =fato_PIB!AF4/100 -> 0.4651 | D7: =fato_PIB!AI4/100 -> 0.0286 | E7: =fato_PIB!AE4/100 -> 0.0169 | F7: =fato_PIB!AH4/100 -> 0.0095
A8: =fato_PIB!A5 -> 2005 | B8: =fato_PIB!AG5/100 -> 0.5493 | C8: =fato_PIB!AF5/100 -> 0.4342 | D8: =fato_PIB!AI5/100 -> 0.0248 | E8: =fato_PIB!AE5/100 -> 0.0148 | F8: =fato_PIB!AH5/100 -> 0.0085
A9: =fato_PIB!A6 -> 2006 | B9: =fato_PIB!AG6/100 -> 0.5258 | C9: =fato_PIB!AF6/100 -> 0.4117 | D9: =fato_PIB!AI6/100 -> 0.023 | E9: =fato_PIB!AE6/100 -> 0.0136 | F9: =fato_PIB!AH6/100 -> 0.0079
A10: =fato_PIB!A7 -> 2007 | B10: =fato_PIB!AG7/100 -> 0.5291 | C10: =fato_PIB!AF7/100 -> 0.4162 | D10: =fato_PIB!AI7/100 -> 0.0234 | E10: =fato_PIB!AE7/100 -> 0.014 | F10: =fato_PIB!AH7/100 -> 0.008
A11: =fato_PIB!A8 -> 2008 | B11: =fato_PIB!AG8/100 -> 0.5282 | C11: =fato_PIB!AF8/100 -> 0.4164 | D11: =fato_PIB!AI8/100 -> 0.0239 | E11: =fato_PIB!AE8/100 -> 0.014 | F11: =fato_PIB!AH8/100 -> 0.008
A12: =fato_PIB!A9 -> 2009 | B12: =fato_PIB!AG9/100 -> 0.5033 | C12: =fato_PIB!AF9/100 -> 0.3949 | D12: =fato_PIB!AI9/100 -> 0.0218 | E12: =fato_PIB!AE9/100 -> 0.0131 | F12: =fato_PIB!AH9/100 -> 0.0074
A13: =fato_PIB!A10 -> 2010 | B13: =fato_PIB!AG10/100 -> 0.494 | C13: =fato_PIB!AF10/100 -> 0.3802 | D13: =fato_PIB!AI10/100 -> 0.02 | E13: =fato_PIB!AE10/100 -> 0.0119 | F13: =fato_PIB!AH10/100 -> 0.0067
A14: =fato_PIB!A11 -> 2011 | B14: =fato_PIB!AG11/100 -> 0.4684 | C14: =fato_PIB!AF11/100 -> 0.3532 | D14: =fato_PIB!AI11/100 -> 0.0178 | E14: =fato_PIB!AE11/100 -> 0.0104 | F14: =fato_PIB!AH11/100 -> 0.0058
A15: =fato_PIB!A12 -> 2012 | B15: =fato_PIB!AG12/100 -> 0.4636 | C15: =fato_PIB!AF12/100 -> 0.3453 | D15: =fato_PIB!AI12/100 -> 0.0171 | E15: =fato_PIB!AE12/100 -> 0.0099 | F15: =fato_PIB!AH12/100 -> 0.0055
A16: =fato_PIB!A13 -> 2013 | B16: =fato_PIB!AG13/100 -> 0.4594 | C16: =fato_PIB!AF13/100 -> 0.3267 | D16: =fato_PIB!AI13/100 -> 0.0165 | E16: =fato_PIB!AE13/100 -> 0.0096 | F16: =fato_PIB!AH13/100 -> 0.0053
... A26: =fato_PIB!A23 -> 2023 | B26: =fato_PIB!AG23/100 -> 0.4885 | C26: =fato_PIB!AF23/100 -> 0.3172 | D26: =fato_PIB!AI23/100 -> 0.0178 | E26: =fato_PIB!AE23/100 -> 0.0106 | F26: =fato_PIB!AH23/100 -> 0.0056
A27: Variação 2002→último (pontos percentuais) | B27: =(B26-B5)*100 -> -7.1 | C27: =(C26-C5)*100 -> -13.49 | D27: =(D26-D5)*100 -> -0.79 | E27: =(E26-E5)*100 -> -0.5 | F27: =(F26-F5)*100 -> -0.34
A29: Micro e mesorregião são as divisões regionais antigas do IBGE (substituídas em 2017 por regiões imediatas e intermediárias), mas a tabela 5938 ainda as usa.
A30: Perder participação não quer dizer encolher: o PIB de SJC cresceu, mas o do estado e do país cresceram mais rápido.

Sheet Cruzamento_RAIS
A1: Emprego formal (RAIS 2024) x valor adicionado (PIB) por setor
A2: Atenção aos anos: vínculos de 2024, VAB por setor de 2021 (último publicado). Use como ordem de grandeza, não como medida exata.
A4: Ano do VAB por setor: | B4: ='LEIA-ME'!B11 -> 2021
A6: Setor do PIB | B6: Vínculos RAIS 2024 | C6: % dos vínculos | D6: % do VAB | E6: VAB em R$ 2023 (R$ bi) | F6: VAB por vínculo (R$ mil, R$ 2023) | G6: Leitura
A7: Agropecuária | B7: =SUMIF(dSetor_CNAE_IBGE!$C$5:$C$25,A7,dSetor_CNAE_IBGE!$E$5:$E$25) -> 624 | C7: =B7/$B$11 -> 0.0030186197 | D7: =INDEX(fato_PIB!$Z$2:$Z$23,MATCH($B$4,fato_PIB!$A$2:$A$23,0))/100 -> 0.000657 | E7: =INDEX(fato_PIB!$P$2:$P$23,MATCH($B$4,fato_PIB!$A$2:$A$23,0))/1000000000 -> 0.028227189 | F7: =IF(A7="Administração pública","não comparável",E7*1000000000/B7/1000) -> 45.23588 | G7: =IF(A7="Administração pública","Emprego público quase ausente na base RAIS",IF(D7>C7,"Produz mais do que emprega","Emprega mais do que produz")) -> Emprega mais do que produz
A8: Indústria | B8: =SUMIF(dSetor_CNAE_IBGE!$C$5:$C$25,A8,dSetor_CNAE_IBGE!$E$5:$E$25) -> 51257 | C8: =B8/$B$11 -> 0.24795735 | D8: =INDEX(fato_PIB!$AA$2:$AA$23,MATCH($B$4,fato_PIB!$A$2:$A$23,0))/100 -> 0.423905 | E8: =INDEX(fato_PIB!$Q$2:$Q$23,MATCH($B$4,fato_PIB!$A$2:$A$23,0))/1000000000 -> 18.216599 | F8: =IF(A8="Administração pública","não comparável",E8*1000000000/B8/1000) -> 355.39729 | G8: =IF(A8="Administração pública","Emprego público quase ausente na base RAIS",IF(D8>C8,"Produz mais do que emprega","Emprega mais do que produz")) -> Produz mais do que emprega
A9: Serviços (exceto adm. pública) | B9: =SUMIF(dSetor_CNAE_IBGE!$C$5:$C$25,A9,dSetor_CNAE_IBGE!$E$5:$E$25) -> 154724 | C9: =B9/$B$11 -> 0.74848222 | D9: =INDEX(fato_PIB!$AB$2:$AB$23,MATCH($B$4,fato_PIB!$A$2:$A$23,0))/100 -> 0.50114 | E9: =INDEX(fato_PIB!$R$2:$R$23,MATCH($B$4,fato_PIB!$A$2:$A$23,0))/1000000000 -> 21.535623 | F9: =IF(A9="Administração pública","não comparável",E9*1000000000/B9/1000) -> 139.18735 | G9: =IF(A9="Administração pública","Emprego público quase ausente na base RAIS",IF(D9>C9,"Produz mais do que emprega","Emprega mais do que produz")) -> Emprega mais do que produz
A10: Administração pública | B10: =SUMIF(dSetor_CNAE_IBGE!$C$5:$C$25,A10,dSetor_CNAE_IBGE!$E$5:$E$25) -> 112 | C10: =B10/$B$11 -> 0.00054180353 | D10: =INDEX(fato_PIB!$AC$2:$AC$23,MATCH($B$4,fato_PIB!$A$2:$A$23,0))/100 -> 0.074298 | E10: =INDEX(fato_PIB!$S$2:$S$23,MATCH($B$4,fato_PIB!$A$2:$A$23,0))/1000000000 -> 3.1928455 | F10: =IF(A10="Administração pública","não comparável",E10*1000000000/B10/1000) -> não comparável | G10: =IF(A10="Administração pública","Emprego público quase ausente na base RAIS",IF(D10>C10,"Produz mais do que emprega","Emprega mais do que produz")) -> Emprego público quase ausente na base RAIS
A11: Total | B11: =SUM(B7:B10) -> 206717 | C11: =SUM(C7:C10) -> 1 | D11: =SUM(D7:D10) -> 1 | E11: =SUM(E7:E10) -> 42.973294
A14: Indicadores gerais
A15: Indicador | B15: Valor | C15: Unidade | D15: Anos usados
A16: PIB por vínculo formal | B16: =INDEX(fato_PIB!$B$2:$B$23,MATCH(MAX(fato_PIB!$A$2:$A$23),fato_PIB!$A$2:$A$23,0))/B11/1000 -> 296.99794 | C16: R$ mil | D16: PIB 2023 / vínculos 2024
A17: Vínculos formais por 1.000 habitantes | B17: =B11/INDEX(dPopulacao!$B$2:$B$100,MATCH(2024,dPopulacao!$A$2:$A$100,0))*1000 -> 285.22289 | C17: vínculos | D17: RAIS 2024 / população 2024
A18: Diferença entre % do VAB e % dos vínculos na indústria | B18: =(D8-C8)*100 -> 17.594765 | C18: pontos percentuais | D18: VAB 2021 / RAIS 2024
A20: A indústria responde por uma fatia do valor adicionado bem maior que sua fatia do emprego formal: produz muito por trabalhador (aeronaves, veículos, refino).
A21: A linha de adm. pública não é comparável: a base RAIS do projeto não traz órgãos públicos, enquanto o VAB do IBGE inclui educação e saúde públicas.

Sheet Deflator_IPCA
A1: Como os valores viram 'R$ de 2023'
A2: Fator de um ano = produto de (1 + IPCA) de todos os anos seguintes até 2023. Ex.: R$ 1 de 2022 = R$ 1,0462 de 2023.
A4: Ano | B4: IPCA no ano (%) | C4: Fator para R$ 2023 (recalculado) | D4: Fator do Colab | E4: Diferença
A5: 2002 | B5: =INDEX(dIPCA!$B$2:$B$100,MATCH(A5,dIPCA!$A$2:$A$100,0)) -> 12.53 | C5: =C6*(1+B6/100) -> 3.3210252 | D5: =INDEX(fato_PIB!$M$2:$M$23,MATCH(A5,fato_PIB!$A$2:$A$23,0)) -> 3.321 | E5: =C5-D5 -> 2.5150539e-05
A6: 2003 | B6: =INDEX(dIPCA!$B$2:$B$100,MATCH(A6,dIPCA!$A$2:$A$100,0)) -> 9.3 | C6: =C7*(1+B7/100) -> 3.0384494 | D6: =INDEX(fato_PIB!$M$2:$M$23,MATCH(A6,fato_PIB!$A$2:$A$23,0)) -> 3.0384 | E6: =C6-D6 -> 4.9360054e-05
A7: 2004 | B7: =INDEX(dIPCA!$B$2:$B$100,MATCH(A7,dIPCA!$A$2:$A$100,0)) -> 7.6 | C7: =C8*(1+B8/100) -> 2.8238377 | D7: =INDEX(fato_PIB!$M$2:$M$23,MATCH(A7,fato_PIB!$A$2:$A$23,0)) -> 2.8238 | E7: =C7-D7 -> 3.7695218e-05
A8: 2005 | B8: =INDEX(dIPCA!$B$2:$B$100,MATCH(A8,dIPCA!$A$2:$A$100,0)) -> 5.69 | C8: =C9*(1+B9/100) -> 2.6718116 | D8: =INDEX(fato_PIB!$M$2:$M$23,MATCH(A8,fato_PIB!$A$2:$A$23,0)) -> 2.6718 | E8: =C8-D8 -> 1.1614361e-05
A9: 2006 | B9: =INDEX(dIPCA!$B$2:$B$100,MATCH(A9,dIPCA!$A$2:$A$100,0)) -> 3.14 | C9: =C10*(1+B10/100) -> 2.5904708 | D9: =INDEX(fato_PIB!$M$2:$M$23,MATCH(A9,fato_PIB!$A$2:$A$23,0)) -> 2.5905 | E9: =C9-D9 -> -2.916971e-05
A10: 2007 | B10: =INDEX(dIPCA!$B$2:$B$100,MATCH(A10,dIPCA!$A$2:$A$100,0)) -> 4.46 | C10: =C11*(1+B11/100) -> 2.4798687 | D10: =INDEX(fato_PIB!$M$2:$M$23,MATCH(A10,fato_PIB!$A$2:$A$23,0)) -> 2.4799 | E10: =C10-D10 -> -3.1313144e-05
A11: 2008 | B11: =INDEX(dIPCA!$B$2:$B$100,MATCH(A11,dIPCA!$A$2:$A$100,0)) -> 5.9 | C11: =C12*(1+B12/100) -> 2.3417079 | D11: =INDEX(fato_PIB!$M$2:$M$23,MATCH(A11,fato_PIB!$A$2:$A$23,0)) -> 2.3417 | E11: =C11-D11 -> 7.9195995e-06
A12: 2009 | B12: =INDEX(dIPCA!$B$2:$B$100,MATCH(A12,dIPCA!$A$2:$A$100,0)) -> 4.31 | C12: =C13*(1+B13/100) -> 2.2449506 | D12: =INDEX(fato_PIB!$M$2:$M$23,MATCH(A12,fato_PIB!$A$2:$A$23,0)) -> 2.245 | E12: =C12-D12 -> -4.9449142e-05
A13: 2010 | B13: =INDEX(dIPCA!$B$2:$B$100,MATCH(A13,dIPCA!$A$2:$A$100,0)) -> 5.91 | C13: =C14*(1+B14/100) -> 2.1196776 | D13: =INDEX(fato_PIB!$M$2:$M$23,MATCH(A13,fato_PIB!$A$2:$A$23,0)) -> 2.1197 | E13: =C13-D13 -> -2.2395565e-05
A14: 2011 | B14: =INDEX(dIPCA!$B$2:$B$100,MATCH(A14,dIPCA!$A$2:$A$100,0)) -> 6.5 | C14: =C15*(1+B15/100) -> 1.9903076 | D14: =INDEX(fato_PIB!$M$2:$M$23,MATCH(A14,fato_PIB!$A$2:$A$23,0)) -> 1.9903 | E14: =C14-D14 -> 7.6097985e-06
A15: 2012 | B15: =INDEX(dIPCA!$B$2:$B$100,MATCH(A15,dIPCA!$A$2:$A$100,0)) -> 5.84 | C15: =C16*(1+B16/100) -> 1.8804872 | D15: =INDEX(fato_PIB!$M$2:$M$23,MATCH(A15,fato_PIB!$A$2:$A$23,0)) -> 1.8805 | E15: =C15-D15 -> -1.2840326e-05
A16: 2013 | B16: =INDEX(dIPCA!$B$2:$B$100,MATCH(A16,dIPCA!$A$2:$A$100,0)) -> 5.91 | C16: =C17*(1+B17/100) -> 1.775552 | D16: =INDEX(fato_PIB!$M$2:$M$23,MATCH(A16,fato_PIB!$A$2:$A$23,0)) -> 1.7756 | E16: =C16-D16 -> -4.7965562e-05
... A25: 2022 | B25: =INDEX(dIPCA!$B$2:$B$100,MATCH(A25,dIPCA!$A$2:$A$100,0)) -> 5.79 | C25: =C26*(1+B26/100) -> 1.0462 | D25: =INDEX(fato_PIB!$M$2:$M$23,MATCH(A25,fato_PIB!$A$2:$A$23,0)) -> 1.0462 | E25: =C25-D25 -> 0
A26: 2023 | B26: =INDEX(dIPCA!$B$2:$B$100,MATCH(A26,dIPCA!$A$2:$A$100,0)) -> 4.62 | C26: 1 | D26: =INDEX(fato_PIB!$M$2:$M$23,MATCH(A26,fato_PIB!$A$2:$A$23,0)) -> 1 | E26: =C26-D26 -> 0
A28: Como corrigir qualquer valor: valor em R$ 2023 = valor do ano × fator do ano.
A29: Escolha do projeto: IPCA de dezembro a dezembro. Outra opção seria o IPCA médio do ano, que combina melhor com um fluxo anual como o PIB; registrar a escolha no Log de Decisões.

Sheet Conferencia
A1: Conferência dos cálculos do Colab
A2: Cada coluna recalcula um indicador e mostra a maior diferença em relação ao valor do Colab.
A4: Ano | B4: Per capita recalc. | C4: Dif. per capita (R$) | D4: PIB R$ 2023 recalc. | E4: Dif. PIB R$ 2023 (R$) | F4: Soma dos setores – VAB total (R$) | G4: VAB + impostos – PIB (R$)
A5: =fato_PIB!A2 -> 2002 | B5: =fato_PIB!B2/fato_PIB!J2 -> 23826.444 | C5: =B5-fato_PIB!X2 -> -4.861625e-05 | D5: =fato_PIB!B2*Deflator_IPCA!C5 -> 4.4288856e+10 | E5: =D5-fato_PIB!N2 -> 0 | F5: =IF(fato_PIB!C2="","sem setor",fato_PIB!D2+fato_PIB!E2+fato_PIB!F2+fato_PIB!G2-fato_PIB!C2) -> -1000 | G5: =IF(fato_PIB!C2="","sem setor",fato_PIB!C2+fato_PIB!H2-fato_PIB!B2) -> 1000
A6: =fato_PIB!A3 -> 2003 | B6: =fato_PIB!B3/fato_PIB!J3 -> 27884.156 | C6: =B6-fato_PIB!X3 -> 4.3881781e-05 | D6: =fato_PIB!B3*Deflator_IPCA!C6 -> 4.8223291e+10 | E6: =D6-fato_PIB!N3 -> 0 | F6: =IF(fato_PIB!C3="","sem setor",fato_PIB!D3+fato_PIB!E3+fato_PIB!F3+fato_PIB!G3-fato_PIB!C3) -> 0 | G6: =IF(fato_PIB!C3="","sem setor",fato_PIB!C3+fato_PIB!H3-fato_PIB!B3) -> 0
A7: =fato_PIB!A4 -> 2004 | B7: =fato_PIB!B4/fato_PIB!J4 -> 31701.229 | C7: =B7-fato_PIB!X4 -> -2.3003158e-06 | D7: =fato_PIB!B4*Deflator_IPCA!C7 -> 5.2731241e+10 | E7: =D7-fato_PIB!N4 -> 0 | F7: =IF(fato_PIB!C4="","sem setor",fato_PIB!D4+fato_PIB!E4+fato_PIB!F4+fato_PIB!G4-fato_PIB!C4) -> 2000 | G7: =IF(fato_PIB!C4="","sem setor",fato_PIB!C4+fato_PIB!H4-fato_PIB!B4) -> -1000
A8: =fato_PIB!A5 -> 2005 | B8: =fato_PIB!B5/fato_PIB!J5 -> 30766.964 | C8: =B8-fato_PIB!X5 -> 3.1270778e-05 | D8: =fato_PIB!B5*Deflator_IPCA!C8 -> 4.9326147e+10 | E8: =D8-fato_PIB!N5 -> 0 | F8: =IF(fato_PIB!C5="","sem setor",fato_PIB!D5+fato_PIB!E5+fato_PIB!F5+fato_PIB!G5-fato_PIB!C5) -> 0 | G8: =IF(fato_PIB!C5="","sem setor",fato_PIB!C5+fato_PIB!H5-fato_PIB!B5) -> 0
A9: =fato_PIB!A6 -> 2006 | B9: =fato_PIB!B6/fato_PIB!J6 -> 31000.542 | C9: =B9-fato_PIB!X6 -> -3.4105062e-05 | D9: =fato_PIB!B6*Deflator_IPCA!C9 -> 4.9064155e+10 | E9: =D9-fato_PIB!N6 -> 0 | F9: =IF(fato_PIB!C6="","sem setor",fato_PIB!D6+fato_PIB!E6+fato_PIB!F6+fato_PIB!G6-fato_PIB!C6) -> 0 | G9: =IF(fato_PIB!C6="","sem setor",fato_PIB!C6+fato_PIB!H6-fato_PIB!B6) -> 0
A10: =fato_PIB!A7 -> 2007 | B10: =fato_PIB!B7/fato_PIB!J7 -> 36744.815 | C10: =B10-fato_PIB!X7 -> -2.712103e-05 | D10: =fato_PIB!B7*Deflator_IPCA!C10 -> 5.4213039e+10 | E10: =D10-fato_PIB!N7 -> 0 | F10: =IF(fato_PIB!C7="","sem setor",fato_PIB!D7+fato_PIB!E7+fato_PIB!F7+fato_PIB!G7-fato_PIB!C7) -> 0 | G10: =IF(fato_PIB!C7="","sem setor",fato_PIB!C7+fato_PIB!H7-fato_PIB!B7) -> 0
A11: =fato_PIB!A8 -> 2008 | B11: =fato_PIB!B8/fato_PIB!J8 -> 40845.621 | C11: =B11-fato_PIB!X8 -> -3.1150354e-05 | D11: =fato_PIB!B8*Deflator_IPCA!C11 -> 5.8271849e+10 | E11: =D11-fato_PIB!N8 -> 0 | F11: =IF(fato_PIB!C8="","sem setor",fato_PIB!D8+fato_PIB!E8+fato_PIB!F8+fato_PIB!G8-fato_PIB!C8) -> 0 | G11: =IF(fato_PIB!C8="","sem setor",fato_PIB!C8+fato_PIB!H8-fato_PIB!B8) -> 0
A12: =fato_PIB!A9 -> 2009 | B12: =fato_PIB!B9/fato_PIB!J9 -> 39888.616 | C12: =B12-fato_PIB!X9 -> -1.5096186e-05 | D12: =fato_PIB!B9*Deflator_IPCA!C12 -> 5.5149999e+10 | E12: =D12-fato_PIB!N9 -> 0 | F12: =IF(fato_PIB!C9="","sem setor",fato_PIB!D9+fato_PIB!E9+fato_PIB!F9+fato_PIB!G9-fato_PIB!C9) -> 1000 | G12: =IF(fato_PIB!C9="","sem setor",fato_PIB!C9+fato_PIB!H9-fato_PIB!B9) -> 0
A13: =fato_PIB!A10 -> 2010 | B13: =fato_PIB!B10/fato_PIB!J10 -> 41033.923 | C13: =B13-fato_PIB!X10 -> 1.4933612e-06 | D13: =fato_PIB!B10*Deflator_IPCA!C13 -> 5.4789702e+10 | E13: =D13-fato_PIB!N10 -> 0 | F13: =IF(fato_PIB!C10="","sem setor",fato_PIB!D10+fato_PIB!E10+fato_PIB!F10+fato_PIB!G10-fato_PIB!C10) -> -1000 | G13: =IF(fato_PIB!C10="","sem setor",fato_PIB!C10+fato_PIB!H10-fato_PIB!B10) -> 1000
A14: =fato_PIB!A11 -> 2011 | B14: =fato_PIB!B11/fato_PIB!J11 -> 40068.616 | C14: =B14-fato_PIB!X11 -> -1.7257989e-05 | D14: =fato_PIB!B11*Deflator_IPCA!C14 -> 5.0790142e+10 | E14: =D14-fato_PIB!N11 -> 0 | F14: =IF(fato_PIB!C11="","sem setor",fato_PIB!D11+fato_PIB!E11+fato_PIB!F11+fato_PIB!G11-fato_PIB!C11) -> 0 | G14: =IF(fato_PIB!C11="","sem setor",fato_PIB!C11+fato_PIB!H11-fato_PIB!B11) -> 0
A15: =fato_PIB!A12 -> 2012 | B15: =fato_PIB!B12/fato_PIB!J12 -> 41306.13 | C15: =B15-fato_PIB!X12 -> 1.0396005e-05 | D15: =fato_PIB!B12*Deflator_IPCA!C15 -> 4.9992279e+10 | E15: =D15-fato_PIB!N12 -> 0 | F15: =IF(fato_PIB!C12="","sem setor",fato_PIB!D12+fato_PIB!E12+fato_PIB!F12+fato_PIB!G12-fato_PIB!C12) -> 0 | G15: =IF(fato_PIB!C12="","sem setor",fato_PIB!C12+fato_PIB!H12-fato_PIB!B12) -> -1000
A16: =fato_PIB!A13 -> 2013 | B16: =fato_PIB!B13/fato_PIB!J13 -> 42019.888 | C16: =B16-fato_PIB!X13 -> -4.7630543e-05 | D16: =fato_PIB!B13*Deflator_IPCA!C16 -> 5.0230545e+10 | E16: =D16-fato_PIB!N13 -> 0 | F16: =IF(fato_PIB!C13="","sem setor",fato_PIB!D13+fato_PIB!E13+fato_PIB!F13+fato_PIB!G13-fato_PIB!C13) -> -1000 | G16: =IF(fato_PIB!C13="","sem setor",fato_PIB!C13+fato_PIB!H13-fato_PIB!B13) -> 0
... A26: =fato_PIB!A23 -> 2023 | B26: =fato_PIB!B23/fato_PIB!J23 -> 86361.081 | C26: =B26-fato_PIB!X23 -> -5.5464479e-06 | D26: =fato_PIB!B23*Deflator_IPCA!C26 -> 61394524000 | E26: =D26-fato_PIB!N23 -> 0 | F26: =IF(fato_PIB!C23="","sem setor",fato_PIB!D23+fato_PIB!E23+fato_PIB!F23+fato_PIB!G23-fato_PIB!C23) -> sem setor | G26: =IF(fato_PIB!C23="","sem setor",fato_PIB!C23+fato_PIB!H23-fato_PIB!B23) -> sem setor
A27: Maior | C27: =MAX(MAX(C5:C26),-MIN(C5:C26)) -> 4.9719645e-05 | E27: =MAX(MAX(E5:E26),-MIN(E5:E26)) -> 0 | F27: =MAX(MAX(F5:F26),-MIN(F5:F26)) -> 2000 | G27: =MAX(MAX(G5:G26),-MIN(G5:G26)) -> 1000
A29: Resultado: os cálculos do Colab conferem. Diferenças de até R$ 2.000 no VAB são arredondamento do IBGE (valores publicados em R$ mil).

Sheet Problemas_Dados
A1: Limitações e problemas nos dados do IBGE
A2: Sugestão: registrar os itens 'Novo' no Log de Decisões de Dados.
A4: Nº | B4: Problema | C4: Afeta | D4: Tratamento sugerido | E4: Status
A5: 1 | B5: O IBGE não publicou o valor adicionado por setor de 2022 e 2023, só o PIB total ('...' no arquivo). O motivo é a mudança do ano de referência das Contas Nacionais (2010 → 2021). | C5: 12 registros (6 variáveis × 2 anos) | D5: Correto deixar vazio (não zero), como o Colab fez. No painel: estrutura setorial até 2021, com nota. | E5: Tratado
A6: 2 | B6: A série 2022–2023 já pode seguir a nova referência do IBGE, e 2002–2021 a antiga. O crescimento de 18,5% em 2022 pode ter parte de efeito metodológico. | C6: Crescimento 2022 | D6: Confirmar nas notas técnicas do IBGE antes de destacar 2022 como 'melhor ano'. | E6: Novo – verificar
A7: 3 | B7: Quebras na série de população: Contagem 2007 (−2,6%), salto de 2013 (+4,6%, nova projeção) e Censo 2022 (−5,5% frente à estimativa de 2021). | C7: PIB per capita em 2007, 2013 e 2022 | D7: Marcar esses anos no gráfico de per capita e explicar na legenda. | E7: Novo
A8: 4 | B8: Não existe estimativa oficial de população para 2023. O Colab interpolou entre Censo 2022 e estimativa 2024 (710.905). | C8: PIB per capita 2023 | D8: Manter e registrar como decisão (DEC) com o método. | E8: Novo – registrar
A9: 5 | B9: A correção pelo IPCA gera crescimento 'deflacionado', não o 'PIB real' oficial (o IBGE não publica volume para municípios). | C9: Todas as colunas *_real_2023 e cresc_real_pct | D9: Chamar de 'deflacionado pelo IPCA' nos rótulos do painel. Avaliar IPCA médio anual em vez de dez/dez. | E9: Novo
A10: 6 | B10: Os arquivos usam formatos diferentes: sidra_* com ponto decimal; fato_* e indicadores com vírgula decimal e 4 casas. | C10: Importação no Power BI | D10: Padronizar no Colab (ex.: tudo com ponto) ou definir a localidade certa em cada importação. | E10: Novo
A11: 7 | B11: As participações regionais aparecem duas vezes: em fato_pib (colunas part_pib_*) e em sidra_5938_participacoes. Os valores são iguais. | C11: Modelo de dados | D11: Usar só uma fonte no Power BI (sugestão: o formato longo de fato_Participacoes). | E11: Novo
A12: 8 | B12: Anos diferentes entre as fontes: RAIS 2024, PIB 2023, VAB por setor 2021. | C12: Todo cruzamento RAIS x PIB | D12: Amplia a DEC-005. Sempre mostrar o ano de cada número no painel. | E12: Ampliar DEC-005
A13: 9 | B13: Micro e mesorregião são divisões regionais antigas (o IBGE criou regiões imediatas e intermediárias em 2017). | C13: Participacao_Regional | D13: Manter, porque é o que a tabela 5938 traz; explicar na legenda. | E13: Informativo
A14: 10 | B14: O log mostra que a coleta usou arquivo local (API indisponível) e que a seção RAIS do notebook não rodou. | C14: Reprodutibilidade | D14: Registrar a data e a origem do arquivo baixado; rodar de novo a seção RAIS com o caminho certo. | E14: Novo
A15: 11 | B15: IPCA vai até 2025 e população até 2026, mas o PIB vai até 2023. | C15: Filtros por ano | D15: No Power BI, limitar o filtro de ano a 2002–2023 nas páginas de PIB. | E15: Informativo
A16: 12 | B16: Diferenças de até R$ 2.000 entre a soma dos setores e o VAB total. | C16: Identidades contábeis | D16: Arredondamento do IBGE (valores em R$ mil). Nenhuma ação. | E16: OK

Sheet Dicionario
A1: Dicionário de dados: o que é cada coluna
A2: Unidade 'R$' = reais (o IBGE publica em R$ mil; o Colab multiplicou por 1.000).
A4: Arquivo | B4: Coluna | C4: Significado | D4: Unidade
A5: fato_pib_sjc_anual | B5: ano | C5: Ano de referência | D5: ano
A6: fato_pib_sjc_anual | B6: pib | C6: Produto Interno Bruto a preços correntes (valor do próprio ano) | D6: R$
A7: fato_pib_sjc_anual | B7: vab_total | C7: Valor adicionado bruto total (PIB sem impostos) | D7: R$
A8: fato_pib_sjc_anual | B8: vab_agropecuaria / vab_industria | C8: Valor adicionado da agropecuária / da indústria (inclui construção e utilidades) | D8: R$
A9: fato_pib_sjc_anual | B9: vab_servicos | C9: Valor adicionado dos serviços, exceto administração pública | D9: R$
A10: fato_pib_sjc_anual | B10: vab_adm_publica | C10: Valor adicionado de administração, defesa, educação e saúde públicas e seguridade | D10: R$
A11: fato_pib_sjc_anual | B11: impostos | C11: Impostos, líquidos de subsídios, sobre produtos | D11: R$
A12: fato_pib_sjc_anual | B12: detalhamento_setorial | C12: 'Completo' = tem VAB por setor; 'Somente PIB total' = 2022 e 2023 | D12: texto
A13: fato_pib_sjc_anual | B13: populacao / fonte_populacao | C13: População usada no per capita e de onde veio | D13: pessoas
A14: fato_pib_sjc_anual | B14: quebra_serie_populacao | C14: Base da população (Censo 2010 ou anterior / Censo 2022) | D14: texto
A15: fato_pib_sjc_anual | B15: fator_ipca_para_2023 | C15: Multiplicador para levar valores do ano a preços de 2023 | D15: fator
... A32: log_tratamento_ibge | B32: etapa / descricao / linhas_afetadas | C32: Registro do que o notebook fez em cada etapa | D32: texto

Sheet Glossario
A1: Glossário em linguagem simples
A3: Termo | B3: O que é | C3: Exemplo com SJC
A4: PIB | B4: Tudo o que foi produzido na cidade no ano, em reais: valor adicionado + impostos sobre produtos. | C4: R$ 61,4 bilhões em 2023.
A5: VAB (valor adicionado bruto) | B5: O valor que cada setor acrescenta: o que vende menos o que gastou com insumos. Somado dá o PIB sem os impostos. | C5: A indústria adicionou R$ 16,5 bi em 2021.
A6: Preços correntes | B6: Valor em reais do próprio ano, sem descontar a inflação. | C6: PIB de 2002: R$ 13,3 bi correntes.
A7: Deflacionar / R$ de 2023 | B7: Corrigir pela inflação para comparar anos diferentes como se todos fossem de 2023. | C7: PIB de 2002 em R$ 2023: R$ 44,3 bi.
A8: IPCA | B8: Índice oficial de inflação do Brasil, calculado pelo IBGE. | C8: 4,62% em 2023.
A9: Crescimento deflacionado | B9: Quanto o PIB em R$ 2023 variou de um ano para o outro. | C9: −13,5% em 2020.
A10: Índice 2010 = 100 | B10: Mostra a evolução em relação a 2010: 112 quer dizer 12% acima de 2010. | C10: 112,1 em 2023.
A11: CAGR (média anual composta) | B11: Taxa constante que levaria do valor inicial ao final no período. | C11: 1,57% ao ano de 2002 a 2023.
A12: PIB per capita | B12: PIB dividido pela população. Mede produção por habitante, não renda das pessoas. | C12: R$ 86.361 em 2023.
A13: Participação | B13: Peso de SJC no total de um recorte maior. | C13: 1,78% do PIB de SP em 2023.
A14: Microrregião / mesorregião | B14: Agrupamentos de municípios usados pelo IBGE até 2017. | C14: SJC é cerca de metade da microrregião.
... A17: Vínculo (RAIS) | B17: Emprego formal ativo em 31/12. Uma pessoa com dois empregos conta duas vezes. | C17: 206.717 vínculos em 2024.

Sheet Sugestoes
A1: Sugestões de organização, visualização e legendas
A3: Tema | B3: Sugestão | C3: Como e por quê
A4: Modelo de dados | B4: Tabela dAno como centro | C4: Uma tabela só com os anos (2002–2026) ligada a fato_PIB, fato_VAB_setorial, dIPCA, dPopulacao e fato_Participacoes. Um filtro de ano controla todas as páginas.
A5: Modelo de dados | B5: Ponte RAIS ↔ PIB | C5: Ligar a RAIS à dSetor_CNAE_IBGE pela seção CNAE e a dSetor à fato_VAB_setorial pelo setor. Assim o mesmo filtro de setor vale para emprego e PIB.
A6: Modelo de dados | B6: Uma fonte por informação | C6: Usar fato_Participacoes (formato longo) e não as colunas part_pib_* repetidas. Usar fato_VAB_setorial para setores.
A7: Modelo de dados | B7: Medidas em vez de colunas prontas | C7: Ex.: PIB per capita = DIVIDE(SUM(fato_PIB[pib]); SUM(fato_PIB[populacao])). Assim o número acompanha o filtro.
A8: Página PIB | B8: Cartões no topo | C8: PIB do último ano, per capita, crescimento do ano, média 2002–2023 e participação em SP. Cada cartão com o ano embaixo.
A9: Página PIB | B9: Linha do PIB em R$ 2023 | C9: Uma linha só, com rótulo nos anos de destaque (2008, 2016, 2020, 2023). Eixo começando em zero.
A10: Página PIB | B10: Colunas de crescimento por ano | C10: Barras acima e abaixo de zero mostram crises e recuperações melhor que a linha.
A11: Página Estrutura | B11: Linhas de participação por setor | C11: Indústria, serviços e adm. pública até 2021; nota explicando por que 2022–2023 não aparecem.
A12: Página Região | B12: Linhas de participação | C12: Separar em dois gráficos: estado/Sudeste/Brasil (até 3%) e micro/meso (até 60%). Escalas muito diferentes não cabem num eixo.
A13: Página Emprego x PIB | B13: Barras agrupadas por setor | C13: % dos vínculos (RAIS) ao lado de % do VAB (IBGE). Mostra que a indústria produz muito por trabalhador.
A14: Legendas e padrão | B14: Mesma cor para o mesmo setor | C14: Indústria sempre na mesma cor em todas as páginas e também na página da RAIS (seções B a F).
... A19: Apresentação | B19: Contar em 3 frases | C19: 1) SJC produz R$ 61 bi e cresce devagar; 2) perde peso no estado; 3) a indústria produz muito com pouco emprego. Cada frase com um gráfico.

Sheet dSetor_CNAE_IBGE
A1: Ponte entre a CNAE (RAIS) e os 4 setores do PIB municipal (IBGE)
A2: Vínculos copiados de CNAE_RAIS_SJC_2024.xlsx, aba Setores_Secao (RAIS 2024, vínculos ativos em 31/12).
A4: Seção CNAE | B4: Nome | C4: Setor no PIB do IBGE | D4: Observação | E4: Vínculos RAIS 2024
A5: A | B5: Agropecuária | C5: Agropecuária | E5: 624
A6: B | B6: Indústrias extrativas | C6: Indústria | E6: 36
A7: C | B7: Indústria de transformação | C7: Indústria | E7: 36989
A8: D | B8: Eletricidade e gás | C8: Indústria | D8: Serviços industriais de utilidade pública | E8: 604
A9: E | B9: Água, esgoto e resíduos | C9: Indústria | D9: Serviços industriais de utilidade pública | E9: 1758
A10: F | B10: Construção | C10: Indústria | D10: No PIB do IBGE a construção faz parte da indústria | E10: 11870
A11: G | B11: Comércio e reparação de veículos | C11: Serviços (exceto adm. pública) | E11: 46228
A12: H | B12: Transporte, armazenagem e correio | C12: Serviços (exceto adm. pública) | E12: 9137
A13: I | B13: Alojamento e alimentação | C13: Serviços (exceto adm. pública) | E13: 10950
A14: J | B14: Informação e comunicação | C14: Serviços (exceto adm. pública) | E14: 5697
A15: K | B15: Atividades financeiras e seguros | C15: Serviços (exceto adm. pública) | E15: 4602
A16: L | B16: Atividades imobiliárias | C16: Serviços (exceto adm. pública) | E16: 750
A17: M | B17: Atividades profissionais, científicas e técnicas | C17: Serviços (exceto adm. pública) | E17: 9234
A18: N | B18: Atividades administrativas | C18: Serviços (exceto adm. pública) | E18: 31396
A19: O | B19: Administração pública | C19: Administração pública | D19: Na base RAIS quase não há órgãos públicos | E19: 112
A20: P | B20: Educação | C20: Serviços (exceto adm. pública) | D20: Na RAIS da base só há escolas privadas; as públicas iriam para adm. pública | E20: 11667
A21: Q | B21: Saúde humana e serviços sociais | C21: Serviços (exceto adm. pública) | D21: Idem: só saúde privada na base | E21: 18824
A22: R | B22: Artes, cultura, esporte e recreação | C22: Serviços (exceto adm. pública) | E22: 1466
A23: S | B23: Outras atividades de serviços | C23: Serviços (exceto adm. pública) | E23: 4769
A24: T | B24: Serviços domésticos | C24: Serviços (exceto adm. pública) | E24: 4
A25: U | B25: Organismos internacionais | C25: Serviços (exceto adm. pública) | E25: 0
A26: Total | E26: =SUM(E5:E25) -> 206717
A28: Use esta tabela no Power BI para ligar a RAIS (por seção CNAE) ao PIB (por setor).

Sheet fato_PIB
A1: ano | B1: pib | C1: vab_total | D1: vab_agropecuaria | E1: vab_industria | F1: vab_servicos | G1: vab_adm_publica | H1: impostos | I1: detalhamento_setorial | J1: populacao | K1: fonte_populacao | L1: quebra_serie_populacao | M1: fator_ipca_para_2023 | N1: pib_real_2023 | O1: vab_total_real_2023 | P1: vab_agropecuaria_real_2023 | Q1: vab_industria_real_2023 | R1: vab_servicos_real_2023 | S1: vab_adm_publica_real_2023 | T1: impostos_real_2023 | U1: cresc_nominal_pct | V1: cresc_real_pct | W1: indice_pib_real_2010_100 | X1: pib_per_capita | Y1: pib_per_capita_real_2023 | Z1: part_agropecuaria_no_vab_pct | AA1: part_industria_no_vab_pct | AB1: part_servicos_no_vab_pct | AC1: part_adm_publica_no_vab_pct | AD1: carga_impostos_no_pib_pct | AE1: part_pib_sudeste_pct | AF1: part_pib_mesorregiao_pct | AG1: part_pib_microrregiao_pct | AH1: part_pib_brasil_pct | AI1: part_pib_estado_sp_pct
A2: 2002 | B2: 13335899000 | C2: 11176044000 | D2: 7360000 | E2: 5894792000 | F2: 4539225000 | G2: 734666000 | H2: 2159856000 | I2: Completo | J2: 559710 | K2: Estimativas da População (tab. 6579) | L2: Base Censo 2010 ou anterior | M2: 3.321 | N2: 4.4288856e+10 | O2: 3.7115923e+10 | P2: 24442745 | Q2: 1.9576752e+10 | R2: 1.507488e+10 | S2: 2.4398443e+09 | T2: 7.1729361e+09 | W2: 80.8343 | X2: 23826.444 | Y2: 79128.22 | Z2: 0.0659 | AA2: 52.7449 | AB2: 40.6157 | AC2: 6.5736 | AD2: 16.1958 | AE2: 1.56 | AF2: 45.21 | AG2: 55.95 | AH2: 0.9 | AI2: 2.57
A3: 2003 | B3: 15871020000 | C3: 13662072000 | D3: 15914000 | E3: 7686678000 | F3: 5123444000 | G3: 836036000 | H3: 2208948000 | I3: Completo | J3: 569177 | K3: Estimativas da População (tab. 6579) | L3: Base Censo 2010 ou anterior | M3: 3.0384 | N3: 4.8223291e+10 | O3: 4.1511514e+10 | P3: 48353883 | Q3: 2.3355582e+10 | R3: 1.5567325e+10 | S3: 2.540253e+09 | T3: 6.7117766e+09 | U3: 19.0097 | V3: 8.8836 | W3: 88.0152 | X3: 27884.156 | Y3: 84724.595 | Z3: 0.1165 | AA3: 56.2629 | AB3: 37.5012 | AC3: 6.1194 | AD3: 13.9181 | AE3: 1.64 | AF3: 45.68 | AG3: 56.05 | AH3: 0.92 | AI3: 2.68
A4: 2004 | B4: 18673609000 | C4: 15717784000 | D4: 17861000 | E4: 9276760000 | F4: 5546388000 | G4: 876777000 | H4: 2955824000 | I4: Completo | J4: 589050 | K4: Estimativas da População (tab. 6579) | L4: Base Censo 2010 ou anterior | M4: 2.8238 | N4: 5.2731241e+10 | O4: 4.4384471e+10 | P4: 50436565 | Q4: 2.6196065e+10 | R4: 1.56621e+10 | S4: 2.4758759e+09 | T4: 8.3467672e+09 | U4: 17.6585 | V4: 9.3481 | W4: 96.243 | X4: 31701.229 | Y4: 89519.126 | Z4: 0.1136 | AA4: 59.0208 | AB4: 35.2873 | AC4: 5.5782 | AD4: 15.8289 | AE4: 1.69 | AF4: 46.51 | AG4: 57.53 | AH4: 0.95 | AI4: 2.86
A5: 2005 | B5: 18461686000 | C5: 15784020000 | D5: 13480000 | E5: 8726268000 | F5: 6034808000 | G5: 1009464000 | H5: 2677666000 | I5: Completo | J5: 600049 | K5: Estimativas da População (tab. 6579) | L5: Base Censo 2010 ou anterior | M5: 2.6718 | N5: 4.9326147e+10 | O5: 4.2171928e+10 | P5: 36016021 | Q5: 2.3314944e+10 | R5: 1.612387e+10 | S5: 2.6970976e+09 | T5: 7.1542191e+09 | U5: -1.1349 | V5: -6.4575 | W5: 90.0281 | X5: 30766.964 | Y5: 82203.532 | Z5: 0.0854 | AA5: 55.2855 | AB5: 38.2337 | AC5: 6.3955 | AD5: 14.5039 | AE5: 1.48 | AF5: 43.42 | AG5: 54.93 | AH5: 0.85 | AI5: 2.48
A6: 2006 | B6: 18940246000 | C6: 16124212000 | D6: 14371000 | E6: 8428423000 | F6: 6555758000 | G6: 1125660000 | H6: 2816034000 | I6: Completo | J6: 610965 | K6: Estimativas da População (tab. 6579) | L6: Base Censo 2010 ou anterior | M6: 2.5905 | N6: 4.9064155e+10 | O6: 4.1769301e+10 | P6: 37227656 | Q6: 2.1833584e+10 | R6: 1.69825e+10 | S6: 2.9159894e+09 | T6: 7.2948539e+09 | U6: 2.5922 | V6: -0.5311 | W6: 89.55 | X6: 31000.542 | Y6: 80305.999 | Z6: 0.0891 | AA6: 52.2718 | AB6: 40.6579 | AC6: 6.9812 | AD6: 14.868 | AE6: 1.36 | AF6: 41.17 | AG6: 52.58 | AH6: 0.79 | AI6: 2.3
A7: 2007 | B7: 21861254000 | C7: 18877332000 | D7: 16963000 | E7: 10386034000 | F7: 7273250000 | G7: 1201085000 | H7: 2983922000 | I7: Completo | J7: 594948 | K7: Contagem da População 2007 (tab. 793) | L7: Base Censo 2010 ou anterior | M7: 2.4799 | N7: 5.4213039e+10 | O7: 4.6813305e+10 | P7: 42066013 | Q7: 2.5756e+10 | R7: 1.8036705e+10 | S7: 2.9785331e+09 | T7: 7.3997347e+09 | U7: 15.4222 | V7: 10.4942 | W7: 98.9475 | X7: 36744.815 | Y7: 91122.315 | Z7: 0.0899 | AA7: 55.0185 | AB7: 38.529 | AC7: 6.3626 | AD7: 13.6494 | AE7: 1.4 | AF7: 41.62 | AG7: 52.91 | AH7: 0.8 | AI7: 2.34
A8: 2008 | B8: 24884337000 | C8: 21175933000 | D8: 14394000 | E8: 11605818000 | F8: 8236812000 | G8: 1318909000 | H8: 3708404000 | I8: Completo | J8: 609229 | K8: Estimativas da População (tab. 6579) | L8: Base Censo 2010 ou anterior | M8: 2.3417 | N8: 5.8271849e+10 | O8: 4.958785e+10 | P8: 33706544 | Q8: 2.7177436e+10 | R8: 1.9288208e+10 | S8: 3.0884997e+09 | T8: 8.683999e+09 | U8: 13.8285 | V8: 7.4868 | W8: 106.3555 | X8: 40845.621 | Y8: 95648.515 | Z8: 0.068 | AA8: 54.8066 | AB8: 38.897 | AC8: 6.2283 | AD8: 14.9026 | AE8: 1.4 | AF8: 41.64 | AG8: 52.82 | AH8: 0.8 | AI8: 2.39
A9: 2009 | B9: 24566242000 | C9: 21313883000 | D9: 18169000 | E9: 10864657000 | F9: 8877586000 | G9: 1553472000 | H9: 3252359000 | I9: Completo | J9: 615871 | K9: Estimativas da População (tab. 6579) | L9: Base Censo 2010 ou anterior | M9: 2.245 | N9: 5.5149999e+10 | O9: 4.7848613e+10 | P9: 40788507 | Q9: 2.4390618e+10 | R9: 1.9929742e+10 | S9: 3.4874678e+09 | T9: 7.3013851e+09 | U9: -1.2783 | V9: -5.3574 | W9: 100.6576 | X9: 39888.616 | Y9: 89547.971 | Z9: 0.0852 | AA9: 50.9746 | AB9: 41.6517 | AC9: 7.2885 | AD9: 13.2391 | AE9: 1.31 | AF9: 39.49 | AG9: 50.33 | AH9: 0.74 | AI9: 2.18
A10: 2010 | B10: 25848130000 | C10: 21878379000 | D10: 18720000 | E10: 10619747000 | F10: 9610221000 | G10: 1629690000 | H10: 3969752000 | I10: Completo | J10: 629921 | K10: Censo 2010 (tab. 1378) | L10: Base Censo 2010 ou anterior | M10: 2.1197 | N10: 5.4789702e+10 | O10: 4.637511e+10 | P10: 39680365 | Q10: 2.251044e+10 | R10: 2.037057e+10 | S10: 3.4544174e+09 | T10: 8.4145944e+09 | U10: 5.2181 | V10: -0.6533 | W10: 100 | X10: 41033.923 | Y10: 86978.688 | Z10: 0.0856 | AA10: 48.5399 | AB10: 43.9257 | AC10: 7.4489 | AD10: 15.358 | AE10: 1.19 | AF10: 38.02 | AG10: 49.4 | AH10: 0.67 | AI10: 2
A11: 2011 | B11: 25518740000 | C11: 21268398000 | D11: 15494000 | E11: 8615541000 | F11: 10938465000 | G11: 1698898000 | H11: 4250342000 | I11: Completo | J11: 636876 | K11: Estimativas da População (tab. 6579) | L11: Base Censo 2010 ou anterior | M11: 1.9903 | N11: 5.0790142e+10 | O11: 4.2330654e+10 | P11: 30837826 | Q11: 1.7147577e+10 | R11: 2.177091e+10 | S11: 3.3813296e+09 | T11: 8.459488e+09 | U11: -1.2743 | V11: -7.2998 | W11: 92.7002 | X11: 40068.616 | Y11: 79748.872 | Z11: 0.0728 | AA11: 40.5087 | AB11: 51.4306 | AC11: 7.9879 | AD11: 16.6558 | AE11: 1.04 | AF11: 35.32 | AG11: 46.84 | AH11: 0.58 | AI11: 1.78
A12: 2012 | B12: 26584749000 | C12: 21934026000 | D12: 16121000 | E12: 7790492000 | F12: 12293119000 | G12: 1834294000 | H12: 4650722000 | I12: Completo | J12: 643603 | K12: Estimativas da População (tab. 6579) | L12: Base Censo 2010 ou anterior | M12: 1.8805 | N12: 4.9992279e+10 | O12: 4.1246654e+10 | P12: 30315334 | Q12: 1.464992e+10 | R12: 2.3117052e+10 | S12: 3.4493663e+09 | T12: 8.745623e+09 | U12: 4.1774 | V12: -1.5709 | W12: 91.2439 | X12: 41306.13 | Y12: 77675.647 | Z12: 0.0735 | AA12: 35.5178 | AB12: 56.0459 | AC12: 8.3628 | AD12: 17.4939 | AE12: 0.99 | AF12: 34.53 | AG12: 46.36 | AH12: 0.55 | AI12: 1.71
A13: 2013 | B13: 28290100000 | C13: 23368234000 | D13: 22714000 | E13: 7537678000 | F13: 13625051000 | G13: 2182790000 | H13: 4921866000 | I13: Completo | J13: 673255 | K13: Estimativas da População (tab. 6579) | L13: Base Censo 2010 ou anterior | M13: 1.7756 | N13: 5.0230545e+10 | O13: 4.1491515e+10 | P13: 40329889 | Q13: 1.338354e+10 | R13: 2.4191987e+10 | S13: 3.8756572e+09 | T13: 8.7390292e+09 | U13: 6.4148 | V13: 0.4766 | W13: 91.6788 | X13: 42019.889 | Y13: 74608.498 | Z13: 0.0972 | AA13: 32.2561 | AB13: 58.3059 | AC13: 9.3408 | AD13: 17.3978 | AE13: 0.96 | AF13: 32.67 | AG13: 45.94 | AH13: 0.53 | AI13: 1.65
A14: 2014 | B14: 30343668000 | C14: 25631204000 | D14: 12442000 | E14: 8739559000 | F14: 14556850000 | G14: 2322353000 | H14: 4712464000 | I14: Completo | J14: 681036 | K14: Estimativas da População (tab. 6579) | L14: Base Censo 2010 ou anterior | M14: 1.6686 | N14: 5.0631295e+10 | O14: 4.2768101e+10 | P14: 20760660 | Q14: 1.4582785e+10 | R14: 2.4289488e+10 | S14: 3.8750668e+09 | T14: 7.8631943e+09 | U14: 7.259 | V14: 0.7978 | W14: 92.4102 | X14: 44555.16 | Y14: 74344.521 | Z14: 0.0485 | AA14: 34.0973 | AB14: 56.7935 | AC14: 9.0606 | AD14: 15.5303 | AE14: 0.96 | AF14: 31.66 | AG14: 46.16 | AH14: 0.53 | AI14: 1.63
... A21: 2021 | B21: 45208808000 | C21: 38827489000 | D21: 25504000 | E21: 16459171000 | F21: 19457996000 | G21: 2884819000 | H21: 6381319000 | I21: Completo | J21: 737310 | K21: Estimativas da População (tab. 6579) | L21: Base Censo 2010 ou anterior | M21: 1.1068 | N21: 5.0035978e+10 | O21: 4.2973293e+10 | P21: 28227189 | Q21: 1.8216599e+10 | R21: 2.1535623e+10 | S21: 3.1928455e+09 | T21: 7.0626842e+09 | U21: 14.8489 | V21: 4.3512 | W21: 91.3237 | X21: 61315.875 | Y21: 67862.877 | Z21: 0.0657 | AA21: 42.3905 | AB21: 50.114 | AC21: 7.4298 | AD21: 14.1152 | AE21: 0.96 | AF21: 28.74 | AG21: 46.18 | AH21: 0.5 | AI21: 1.66
A22: 2022 | B22: 56653327000 | I22: Somente PIB total | J22: 697054 | K22: Censo 2022 (tab. 4709) | L22: Base Censo 2022 | M22: 1.0462 | N22: 5.9270711e+10 | U22: 25.3148 | V22: 18.4562 | W22: 108.1786 | X22: 81275.378 | Y22: 85030.3 | AE22: 1.05 | AF22: 29.67 | AG22: 49.64 | AH22: 0.56 | AI22: 1.81
A23: 2023 | B23: 61394524000 | I23: Somente PIB total | J23: 710905 | K23: Interpolação linear (tratamento do projeto) | L23: Base Censo 2022 | M23: 1 | N23: 61394524000 | U23: 8.3688 | V23: 3.5832 | W23: 112.0549 | X23: 86361.081 | Y23: 86361.081 | AE23: 1.06 | AF23: 31.72 | AG23: 48.85 | AH23: 0.56 | AI23: 1.78

Sheet fato_VAB_setorial
A1: ano | B1: cod_setor | C1: setor | D1: vab_corrente | E1: vab_real_2023 | F1: participacao_no_vab_pct | G1: cresc_real_pct
A2: 2002 | B2: vab_adm_publica | C2: Administração pública, defesa, educação e saúde públicas | D2: 734666000 | E2: 2.4398443e+09 | F2: 6.5736
A3: 2003 | B3: vab_adm_publica | C3: Administração pública, defesa, educação e saúde públicas | D3: 836036000 | E3: 2.540253e+09 | F3: 6.1194 | G3: 4.1154
A4: 2004 | B4: vab_adm_publica | C4: Administração pública, defesa, educação e saúde públicas | D4: 876777000 | E4: 2.4758759e+09 | F4: 5.5782 | G4: -2.5343
A5: 2005 | B5: vab_adm_publica | C5: Administração pública, defesa, educação e saúde públicas | D5: 1009464000 | E5: 2.6970976e+09 | F5: 6.3955 | G5: 8.9351
A6: 2006 | B6: vab_adm_publica | C6: Administração pública, defesa, educação e saúde públicas | D6: 1125660000 | E6: 2.9159894e+09 | F6: 6.9812 | G6: 8.1158
A7: 2007 | B7: vab_adm_publica | C7: Administração pública, defesa, educação e saúde públicas | D7: 1201085000 | E7: 2.9785331e+09 | F7: 6.3626 | G7: 2.1449
A8: 2008 | B8: vab_adm_publica | C8: Administração pública, defesa, educação e saúde públicas | D8: 1318909000 | E8: 3.0884997e+09 | F8: 6.2283 | G8: 3.692
A9: 2009 | B9: vab_adm_publica | C9: Administração pública, defesa, educação e saúde públicas | D9: 1553472000 | E9: 3.4874678e+09 | F9: 7.2885 | G9: 12.9179
A10: 2010 | B10: vab_adm_publica | C10: Administração pública, defesa, educação e saúde públicas | D10: 1629690000 | E10: 3.4544174e+09 | F10: 7.4489 | G10: -0.9477
A11: 2011 | B11: vab_adm_publica | C11: Administração pública, defesa, educação e saúde públicas | D11: 1698898000 | E11: 3.3813296e+09 | F11: 7.9879 | G11: -2.1158
A12: 2012 | B12: vab_adm_publica | C12: Administração pública, defesa, educação e saúde públicas | D12: 1834294000 | E12: 3.4493663e+09 | F12: 8.3628 | G12: 2.0121
A13: 2013 | B13: vab_adm_publica | C13: Administração pública, defesa, educação e saúde públicas | D13: 2182790000 | E13: 3.8756572e+09 | F13: 9.3408 | G13: 12.3585
